{"uuid": "e5e5ae3e-e7fa-4b9d-88be-5a847f50a370", "children": ["273d25bc-16e6-417f-9947-34e63603f15b"], "befores": [{"name": "open_url1", "status": "broken", "statusDetails": {"message": "selenium.common.exceptions.WebDriverException: Message: unknown error: unhandled inspector error: {\"code\":-32000,\"message\":\"Cannot navigate to invalid URL\"}\n  (Session info: chrome=73.0.3683.103)\n  (Driver info: chromedriver=2.36.540470 (e522d04694c7ebea4ba8821272dbef4f9b818c91),platform=Windows NT 6.1.7601 SP1 x86_64)\n\n", "trace": "  File \"E:\\Python3\\lib\\site-packages\\pluggy\\callers.py\", line 187, in _multicall\n    res = hook_impl.function(*args)\n  File \"E:\\Python3\\lib\\site-packages\\_pytest\\fixtures.py\", line 937, in pytest_fixture_setup\n    result = call_fixture_func(fixturefunc, request, kwargs)\n  File \"E:\\Python3\\lib\\site-packages\\_pytest\\fixtures.py\", line 790, in call_fixture_func\n    res = next(it)\n  File \"D:\\B2B\\Testcases\\m\\conftest.py\", line 45, in open_url1\n    driver.get('m.vsigo.cn')\n  File \"E:\\Python3\\lib\\site-packages\\selenium\\webdriver\\remote\\webdriver.py\", line 333, in get\n    self.execute(Command.GET, {'url': url})\n  File \"E:\\Python3\\lib\\site-packages\\selenium\\webdriver\\remote\\webdriver.py\", line 321, in execute\n    self.error_handler.check_response(response)\n  File \"E:\\Python3\\lib\\site-packages\\selenium\\webdriver\\remote\\errorhandler.py\", line 242, in check_response\n    raise exception_class(message, screen, stacktrace)\n"}, "start": 1576584828311, "stop": 1576584833798}], "start": 1576584828311, "stop": 1576584834111}